[2025-05-28T10:14:39.743+0000] {taskinstance.py:1956} INFO - Dependencies all met for dep_context=non-requeueable deps ti=<TaskInstance: etl_api_to_sqlite.load_api_task manual__2025-05-28T10:14:34.635530+00:00 [queued]>
[2025-05-28T10:14:39.756+0000] {taskinstance.py:1956} INFO - Dependencies all met for dep_context=requeueable deps ti=<TaskInstance: etl_api_to_sqlite.load_api_task manual__2025-05-28T10:14:34.635530+00:00 [queued]>
[2025-05-28T10:14:39.758+0000] {taskinstance.py:2170} INFO - Starting attempt 1 of 2
[2025-05-28T10:14:39.771+0000] {taskinstance.py:2191} INFO - Executing <Task(PythonOperator): load_api_task> on 2025-05-28 10:14:34.635530+00:00
[2025-05-28T10:14:39.780+0000] {standard_task_runner.py:60} INFO - Started process 257 to run task
[2025-05-28T10:14:39.782+0000] {standard_task_runner.py:87} INFO - Running: ['***', 'tasks', 'run', 'etl_api_to_sqlite', 'load_api_task', 'manual__2025-05-28T10:14:34.635530+00:00', '--job-id', '17', '--raw', '--subdir', 'DAGS_FOLDER/etl_api_to_sqlite.py', '--cfg-path', '/tmp/tmpcaxbs5w6']
[2025-05-28T10:14:39.786+0000] {standard_task_runner.py:88} INFO - Job 17: Subtask load_api_task
[2025-05-28T10:14:39.839+0000] {task_command.py:423} INFO - Running <TaskInstance: etl_api_to_sqlite.load_api_task manual__2025-05-28T10:14:34.635530+00:00 [running]> on host f1bd559e8a8b
[2025-05-28T10:14:39.910+0000] {taskinstance.py:2480} INFO - Exporting env vars: AIRFLOW_CTX_DAG_OWNER='***' AIRFLOW_CTX_DAG_ID='etl_api_to_sqlite' AIRFLOW_CTX_TASK_ID='load_api_task' AIRFLOW_CTX_EXECUTION_DATE='2025-05-28T10:14:34.635530+00:00' AIRFLOW_CTX_TRY_NUMBER='1' AIRFLOW_CTX_DAG_RUN_ID='manual__2025-05-28T10:14:34.635530+00:00'
[2025-05-28T10:14:40.193+0000] {taskinstance.py:2698} ERROR - Task failed with exception
Traceback (most recent call last):
  File "/home/airflow/.local/lib/python3.8/site-packages/airflow/models/taskinstance.py", line 433, in _execute_task
    result = execute_callable(context=context, **execute_callable_kwargs)
  File "/home/airflow/.local/lib/python3.8/site-packages/airflow/operators/python.py", line 199, in execute
    return_value = self.execute_callable()
  File "/home/airflow/.local/lib/python3.8/site-packages/airflow/operators/python.py", line 216, in execute_callable
    return self.python_callable(*self.op_args, **self.op_kwargs)
  File "/opt/airflow/dags/etl_api_to_sqlite.py", line 89, in load_api_data
    df.to_sql('posts', conn, if_exists='replace', index=False)
  File "/home/airflow/.local/lib/python3.8/site-packages/pandas/core/generic.py", line 2878, in to_sql
    return sql.to_sql(
  File "/home/airflow/.local/lib/python3.8/site-packages/pandas/io/sql.py", line 769, in to_sql
    return pandas_sql.to_sql(
  File "/home/airflow/.local/lib/python3.8/site-packages/pandas/io/sql.py", line 2378, in to_sql
    table.create()
  File "/home/airflow/.local/lib/python3.8/site-packages/pandas/io/sql.py", line 914, in create
    self._execute_create()
  File "/home/airflow/.local/lib/python3.8/site-packages/pandas/io/sql.py", line 2052, in _execute_create
    conn.execute(stmt)
sqlite3.OperationalError: table "posts" already exists
[2025-05-28T10:14:40.218+0000] {taskinstance.py:1138} INFO - Marking task as UP_FOR_RETRY. dag_id=etl_api_to_sqlite, task_id=load_api_task, execution_date=20250528T101434, start_date=20250528T101439, end_date=20250528T101440
[2025-05-28T10:14:40.236+0000] {standard_task_runner.py:107} ERROR - Failed to execute job 17 for task load_api_task (table "posts" already exists; 257)
[2025-05-28T10:14:40.281+0000] {local_task_job_runner.py:234} INFO - Task exited with return code 1
[2025-05-28T10:14:40.298+0000] {taskinstance.py:3280} INFO - 0 downstream tasks scheduled from follow-on schedule check
